Traceback (most recent call last):
  File "/Users/mhjensen/miniforge3/lib/python3.9/site-packages/jupyter_cache/executors/utils.py", line 58, in single_nb_execution
    executenb(
  File "/Users/mhjensen/miniforge3/lib/python3.9/site-packages/nbclient/client.py", line 1305, in execute
    return NotebookClient(nb=nb, resources=resources, km=km, **kwargs).execute()
  File "/Users/mhjensen/miniforge3/lib/python3.9/site-packages/jupyter_core/utils/__init__.py", line 166, in wrapped
    return loop.run_until_complete(inner)
  File "/Users/mhjensen/miniforge3/lib/python3.9/asyncio/base_events.py", line 647, in run_until_complete
    return future.result()
  File "/Users/mhjensen/miniforge3/lib/python3.9/site-packages/nbclient/client.py", line 705, in async_execute
    await self.async_execute_cell(
  File "/Users/mhjensen/miniforge3/lib/python3.9/site-packages/nbclient/client.py", line 1058, in async_execute_cell
    await self._check_raise_for_error(cell, cell_index, exec_reply)
  File "/Users/mhjensen/miniforge3/lib/python3.9/site-packages/nbclient/client.py", line 914, in _check_raise_for_error
    raise CellExecutionError.from_cell_and_msg(cell, exec_reply_content)
nbclient.exceptions.CellExecutionError: An error occurred while executing the following cell:
------------------
x = np.random.rand(100,1)
y = 2.0+5*x*x+0.1*np.random.randn(100,1)
------------------


[0;31m---------------------------------------------------------------------------[0m
[0;31mNameError[0m                                 Traceback (most recent call last)
Cell [0;32mIn[1], line 1[0m
[0;32m----> 1[0m x [38;5;241m=[39m [43mnp[49m[38;5;241m.[39mrandom[38;5;241m.[39mrand([38;5;241m100[39m,[38;5;241m1[39m)
[1;32m      2[0m y [38;5;241m=[39m [38;5;241m2.0[39m[38;5;241m+[39m[38;5;241m5[39m[38;5;241m*[39mx[38;5;241m*[39mx[38;5;241m+[39m[38;5;241m0.1[39m[38;5;241m*[39mnp[38;5;241m.[39mrandom[38;5;241m.[39mrandn([38;5;241m100[39m,[38;5;241m1[39m)

[0;31mNameError[0m: name 'np' is not defined

